Workbook

Sheet 前端功能清单
A1: 功能编号 | B1: 一级模块 | C1: 二级模块 | D1: 三级模块 | E1: 功能说明 | F1: 设计说明 | G1: 负责人 | H1: 状态 | I1: 备注 | J1: 预估人天 | K1: 实际耗时 | L1: 完成度
A2: F-01 | B2: 管理空间 | C2: 画布管理页 | D2: 画布列表与管理 | E2: 新建画布/导入画布(上传JSON)/画布列表缩略图展示/编辑画布名称/删除画布(二次确认)/下载画布(导出JSON) | H2: 未开始 | J2: =SUMIF(任务清单!A:A,A2,任务清单!I:I) | K2: =SUMIF(任务清单!A:A,A2,任务清单!J:J) | L2: =IF(SUMIF(任务清单!A:A,A2,任务清单!I:I)=0,0,(SUMIFS(任务清单!I:I,任务清单!A:A,A2,任务清单!O:O,"已完成")+SUMIFS(任务清单!I:I,任务清单!A:A,A2,任务清单!O:O,"已取消"))/SUMIF(任务清单!A:A,A2,任务清单!I:I))
A3: F-02 | B3: 管理空间 | C3: 无限画布 | D3: 画布基础操作 | E3: 无限延展创作空间/画布拖拽平移/画布缩放(放大缩小)/适应视图/一键整理/鼠标模式切换(选择/抓手) | H3: 未开始 | J3: =SUMIF(任务清单!A:A,A3,任务清单!I:I) | K3: =SUMIF(任务清单!A:A,A3,任务清单!J:J) | L3: =IF(SUMIF(任务清单!A:A,A3,任务清单!I:I)=0,0,(SUMIFS(任务清单!I:I,任务清单!A:A,A3,任务清单!O:O,"已完成")+SUMIFS(任务清单!I:I,任务清单!A:A,A3,任务清单!O:O,"已取消"))/SUMIF(任务清单!A:A,A3,任务清单!I:I))
A4: F-03 | B4: 管理空间 | C4: 卡片管理 | D4: 卡片(节点)操作 | E4: 新建卡片(左侧按钮/右键/双击3种方式)/卡片拖拽移动/卡片缩放/卡片复制/卡片删除/多卡片框选/卡片编辑(修改内容参数) | H4: 未开始 | J4: =SUMIF(任务清单!A:A,A4,任务清单!I:I) | K4: =SUMIF(任务清单!A:A,A4,任务清单!J:J) | L4: =IF(SUMIF(任务清单!A:A,A4,任务清单!I:I)=0,0,(SUMIFS(任务清单!I:I,任务清单!A:A,A4,任务清单!O:O,"已完成")+SUMIFS(任务清单!I:I,任务清单!A:A,A4,任务清单!O:O,"已取消"))/SUMIF(任务清单!A:A,A4,任务清单!I:I))
A5: F-04 | B5: 管理空间 | C5: 连线系统 | D5: 节点连线功能 | E5: 添加连线(输出端→输入端)/通过输出端呼出模态列表一键创建下游节点/删除连线/连线状态可视化(蓝色有效/灰色无效/黑色选中) | H5: 未开始 | J5: =SUMIF(任务清单!A:A,A5,任务清单!I:I) | K5: =SUMIF(任务清单!A:A,A5,任务清单!J:J) | L5: =IF(SUMIF(任务清单!A:A,A5,任务清单!I:I)=0,0,(SUMIFS(任务清单!I:I,任务清单!A:A,A5,任务清单!O:O,"已完成")+SUMIFS(任务清单!I:I,任务清单!A:A,A5,任务清单!O:O,"已取消"))/SUMIF(任务清单!A:A,A5,任务清单!I:I))
A6: F-05 | B6: 管理空间 | C6: 编组功能 | D6: 节点编组管理 | E6: 框选多卡片编组/编组颜色选择/网格排列(自动网格布局)/水平排列(自动水平布局)/取消编组/下载编组内所有内容 | H6: 未开始 | J6: =SUMIF(任务清单!A:A,A6,任务清单!I:I) | K6: =SUMIF(任务清单!A:A,A6,任务清单!J:J) | L6: =IF(SUMIF(任务清单!A:A,A6,任务清单!I:I)=0,0,(SUMIFS(任务清单!I:I,任务清单!A:A,A6,任务清单!O:O,"已完成")+SUMIFS(任务清单!I:I,任务清单!A:A,A6,任务清单!O:O,"已取消"))/SUMIF(任务清单!A:A,A6,任务清单!I:I))
A7: F-06 | B7: 管理空间 | C7: 堆叠功能 | D7: 节点堆叠管理 | E7: 框选多卡片堆叠为一张卡片(拼图预览)/双击展开堆叠卡片/点击空白重新堆叠/拉出到画布(单独拉出某卡片) | H7: 未开始 | J7: =SUMIF(任务清单!A:A,A7,任务清单!I:I) | K7: =SUMIF(任务清单!A:A,A7,任务清单!J:J) | L7: =IF(SUMIF(任务清单!A:A,A7,任务清单!I:I)=0,0,(SUMIFS(任务清单!I:I,任务清单!A:A,A7,任务清单!O:O,"已完成")+SUMIFS(任务清单!I:I,任务清单!A:A,A7,任务清单!O:O,"已取消"))/SUMIF(任务清单!A:A,A7,任务清单!I:I))
A8: F-07 | B8: 内容卡片 | C8: 文本卡片 | D8: 文本卡片创作 | E8: 文本编辑(Markdown/富文本)/上传参考/AI文本生成/模型选择/生成份数/消耗预览/保存至素材库/生成历史 | H8: 未开始 | J8: =SUMIF(任务清单!A:A,A8,任务清单!I:I) | K8: =SUMIF(任务清单!A:A,A8,任务清单!J:J) | L8: =IF(SUMIF(任务清单!A:A,A8,任务清单!I:I)=0,0,(SUMIFS(任务清单!I:I,任务清单!A:A,A8,任务清单!O:O,"已完成")+SUMIFS(任务清单!I:I,任务清单!A:A,A8,任务清单!O:O,"已取消"))/SUMIF(任务清单!A:A,A8,任务清单!I:I))
A9: F-08 | B9: 内容卡片 | C9: 图片卡片 | D9: 图片卡片创作 | E9: 图片上传/AI图片生成/参数选择(分辨率/风格/份数)/消耗预览/生成历史列表/下载/保存素材库/全屏预览 | H9: 未开始 | J9: =SUMIF(任务清单!A:A,A9,任务清单!I:I) | K9: =SUMIF(任务清单!A:A,A9,任务清单!J:J) | L9: =IF(SUMIF(任务清单!A:A,A9,任务清单!I:I)=0,0,(SUMIFS(任务清单!I:I,任务清单!A:A,A9,任务清单!O:O,"已完成")+SUMIFS(任务清单!I:I,任务清单!A:A,A9,任务清单!O:O,"已取消"))/SUMIF(任务清单!A:A,A9,任务清单!I:I))
A10: F-09 | B10: 内容卡片 | C10: 视频卡片 | D10: 视频卡片创作 | E10: AI生成视频(调用模型)/模型选择/参数选择(运镜/风格/份数)/消耗预览/剪辑(拖动首尾边界)/提取帧(截取当前帧)/超分(选择分辨率)/认证(Seedance 2.0)/下载/存入素材库/全屏展示 | H10: 未开始 | J10: =SUMIF(任务清单!A:A,A10,任务清单!I:I) | K10: =SUMIF(任务清单!A:A,A10,任务清单!J:J) | L10: =IF(SUMIF(任务清单!A:A,A10,任务清单!I:I)=0,0,(SUMIFS(任务清单!I:I,任务清单!A:A,A10,任务清单!O:O,"已完成")+SUMIFS(任务清单!I:I,任务清单!A:A,A10,任务清单!O:O,"已取消"))/SUMIF(任务清单!A:A,A10,任务清单!I:I))
A11: F-10 | B11: 内容卡片 | C11: 音频卡片 | D11: 音频卡片创作 | E11: 上传参考/AI生成音频/模型选择/参数选择(风格/份数)/消耗预览/试听/下载/存入素材库 | H11: 未开始 | J11: =SUMIF(任务清单!A:A,A11,任务清单!I:I) | K11: =SUMIF(任务清单!A:A,A11,任务清单!J:J) | L11: =IF(SUMIF(任务清单!A:A,A11,任务清单!I:I)=0,0,(SUMIFS(任务清单!I:I,任务清单!A:A,A11,任务清单!O:O,"已完成")+SUMIFS(任务清单!I:I,任务清单!A:A,A11,任务清单!O:O,"已取消"))/SUMIF(任务清单!A:A,A11,任务清单!I:I))
A12: F-11 | B12: 生成增强 | C12: 合成节点 | D12: 视频合成节点 | E12: 接收多个视频节点输入/多段视频拼接预览/点击合成完成拼接/消耗预览/下载合成结果 | H12: 未开始 | J12: =SUMIF(任务清单!A:A,A12,任务清单!I:I) | K12: =SUMIF(任务清单!A:A,A12,任务清单!J:J) | L12: =IF(SUMIF(任务清单!A:A,A12,任务清单!I:I)=0,0,(SUMIFS(任务清单!I:I,任务清单!A:A,A12,任务清单!O:O,"已完成")+SUMIFS(任务清单!I:I,任务清单!A:A,A12,任务清单!O:O,"已取消"))/SUMIF(任务清单!A:A,A12,任务清单!I:I))
A13: F-12 | B13: 生成增强 | C13: 导演台 | D13: 导演台节点 | E13: 作为图片/视频节点上游输入/进入导演台编辑页/新增模型(从列表选择)/修改模型参数(场景/人物/颜色/位置/大小/姿势)/拖拽滚轴调整参数/删除模型/调整视角/拍照(生成当前场景截图输出) | H13: 未开始 | J13: =SUMIF(任务清单!A:A,A13,任务清单!I:I) | K13: =SUMIF(任务清单!A:A,A13,任务清单!J:J) | L13: =IF(SUMIF(任务清单!A:A,A13,任务清单!I:I)=0,0,(SUMIFS(任务清单!I:I,任务清单!A:A,A13,任务清单!O:O,"已完成")+SUMIFS(任务清单!I:I,任务清单!A:A,A13,任务清单!O:O,"已取消"))/SUMIF(任务清单!A:A,A13,任务清单!I:I))
... A35: F-34 | B35: 通用 | C35: 状态处理 | D35: 生成状态与异常处理 | E35: 卡片生成状态展示(排队/执行/成功/失败)/失败原因展示/重试/取消/点数不足提示/充值入口/校验必填参数/模型状态 | H35: 未开始 | J35: =SUMIF(任务清单!A:A,A35,任务清单!I:I) | K35: =SUMIF(任务清单!A:A,A35,任务清单!J:J) | L35: =IF(SUMIF(任务清单!A:A,A35,任务清单!I:I)=0,0,(SUMIFS(任务清单!I:I,任务清单!A:A,A35,任务清单!O:O,"已完成")+SUMIFS(任务清单!I:I,任务清单!A:A,A35,任务清单!O:O,"已取消"))/SUMIF(任务清单!A:A,A35,任务清单!I:I))

Sheet 后端功能清单
A1: 功能编号 | B1: 一级模块 | C1: 二级模块 | D1: 三级模块 | E1: 功能说明 | F1: 设计说明 | G1: 负责人 | H1: 状态 | I1: 备注 | J1: 预估人天 | K1: 实际耗时 | L1: 完成度
A2: B-01 | B2: 管理空间 | C2: 画布服务 | D2: 画布CRUD API | E2: 画布创建/查询/更新/删除API/画布列表分页查询/缩略图生成/权限校验(仅所有者操作) | H2: 未开始 | J2: =SUMIF(任务清单!A:A,A2,任务清单!I:I) | K2: =SUMIF(任务清单!A:A,A2,任务清单!J:J) | L2: =IF(SUMIF(任务清单!A:A,A2,任务清单!I:I)=0,0,(SUMIFS(任务清单!I:I,任务清单!A:A,A2,任务清单!O:O,"已完成")+SUMIFS(任务清单!I:I,任务清单!A:A,A2,任务清单!O:O,"已取消"))/SUMIF(任务清单!A:A,A2,任务清单!I:I))
A3: B-02 | B3: 管理空间 | C3: 画布服务 | D3: 画布导入导出API | E3: 画布JSON序列化导出/JSON导入还原/版本号校验/格式兼容性检测/大画布性能优化 | H3: 未开始 | J3: =SUMIF(任务清单!A:A,A3,任务清单!I:I) | K3: =SUMIF(任务清单!A:A,A3,任务清单!J:J) | L3: =IF(SUMIF(任务清单!A:A,A3,任务清单!I:I)=0,0,(SUMIFS(任务清单!I:I,任务清单!A:A,A3,任务清单!O:O,"已完成")+SUMIFS(任务清单!I:I,任务清单!A:A,A3,任务清单!O:O,"已取消"))/SUMIF(任务清单!A:A,A3,任务清单!I:I))
A4: B-03 | B4: 管理空间 | C4: 画布服务 | D4: 画布数据存储API | E4: 节点数据存储(位置/类型/参数/状态)/连线数据存储/编组堆叠数据/画布自动保存/并发写入版本控制 | H4: 未开始 | J4: =SUMIF(任务清单!A:A,A4,任务清单!I:I) | K4: =SUMIF(任务清单!A:A,A4,任务清单!J:J) | L4: =IF(SUMIF(任务清单!A:A,A4,任务清单!I:I)=0,0,(SUMIFS(任务清单!I:I,任务清单!A:A,A4,任务清单!O:O,"已完成")+SUMIFS(任务清单!I:I,任务清单!A:A,A4,任务清单!O:O,"已取消"))/SUMIF(任务清单!A:A,A4,任务清单!I:I))
A5: B-04 | B5: 管理空间 | C5: 连线服务 | D5: 连线与管理API | E5: 连线校验规则(兼容性/自连接/重复连接阻止)/节点类型列表API/下游数据引用解析 | H5: 未开始 | J5: =SUMIF(任务清单!A:A,A5,任务清单!I:I) | K5: =SUMIF(任务清单!A:A,A5,任务清单!J:J) | L5: =IF(SUMIF(任务清单!A:A,A5,任务清单!I:I)=0,0,(SUMIFS(任务清单!I:I,任务清单!A:A,A5,任务清单!O:O,"已完成")+SUMIFS(任务清单!I:I,任务清单!A:A,A5,任务清单!O:O,"已取消"))/SUMIF(任务清单!A:A,A5,任务清单!I:I))
A6: B-05 | B6: 内容生成 | C6: 文本服务 | D6: 文本生成API | E6: AI文本生成接口/提示词校验/Markdown内容存储/上传参考处理 | H6: 未开始 | J6: =SUMIF(任务清单!A:A,A6,任务清单!I:I) | K6: =SUMIF(任务清单!A:A,A6,任务清单!J:J) | L6: =IF(SUMIF(任务清单!A:A,A6,任务清单!I:I)=0,0,(SUMIFS(任务清单!I:I,任务清单!A:A,A6,任务清单!O:O,"已完成")+SUMIFS(任务清单!I:I,任务清单!A:A,A6,任务清单!O:O,"已取消"))/SUMIF(任务清单!A:A,A6,任务清单!I:I))
A7: B-06 | B7: 内容生成 | C7: 图片服务 | D7: 图片生成API | E7: 图片生成接口/多分辨率支持/风格参数映射/多份生成/图片裁剪(单图四宫格九宫格)/超分/扩图/认证(Seedance 2.0)/生成历史存储 | H7: 未开始 | J7: =SUMIF(任务清单!A:A,A7,任务清单!I:I) | K7: =SUMIF(任务清单!A:A,A7,任务清单!J:J) | L7: =IF(SUMIF(任务清单!A:A,A7,任务清单!I:I)=0,0,(SUMIFS(任务清单!I:I,任务清单!A:A,A7,任务清单!O:O,"已完成")+SUMIFS(任务清单!I:I,任务清单!A:A,A7,任务清单!O:O,"已取消"))/SUMIF(任务清单!A:A,A7,任务清单!I:I))
A8: B-07 | B8: 内容生成 | C8: 视频服务 | D8: 视频生成API | E8: 视频生成接口/运镜参数映射/剪辑范围处理/帧提取/超分/认证(Seedance 2.0)/生成历史存储 | H8: 未开始 | J8: =SUMIF(任务清单!A:A,A8,任务清单!I:I) | K8: =SUMIF(任务清单!A:A,A8,任务清单!J:J) | L8: =IF(SUMIF(任务清单!A:A,A8,任务清单!I:I)=0,0,(SUMIFS(任务清单!I:I,任务清单!A:A,A8,任务清单!O:O,"已完成")+SUMIFS(任务清单!I:I,任务清单!A:A,A8,任务清单!O:O,"已取消"))/SUMIF(任务清单!A:A,A8,任务清单!I:I))
A9: B-08 | B9: 内容生成 | C9: 音频服务 | D9: 音频生成API | E9: 音频生成接口/风格参数映射/多份生成/生成历史存储 | H9: 未开始 | J9: =SUMIF(任务清单!A:A,A9,任务清单!I:I) | K9: =SUMIF(任务清单!A:A,A9,任务清单!J:J) | L9: =IF(SUMIF(任务清单!A:A,A9,任务清单!I:I)=0,0,(SUMIFS(任务清单!I:I,任务清单!A:A,A9,任务清单!O:O,"已完成")+SUMIFS(任务清单!I:I,任务清单!A:A,A9,任务清单!O:O,"已取消"))/SUMIF(任务清单!A:A,A9,任务清单!I:I))
A10: B-09 | B10: 生成增强 | C10: 合成服务 | D10: 视频合成API | E10: 多视频节点输入接收/视频拼接/合成任务队列/消耗计算/结果回调 | H10: 未开始 | J10: =SUMIF(任务清单!A:A,A10,任务清单!I:I) | K10: =SUMIF(任务清单!A:A,A10,任务清单!J:J) | L10: =IF(SUMIF(任务清单!A:A,A10,任务清单!I:I)=0,0,(SUMIFS(任务清单!I:I,任务清单!A:A,A10,任务清单!O:O,"已完成")+SUMIFS(任务清单!I:I,任务清单!A:A,A10,任务清单!O:O,"已取消"))/SUMIF(任务清单!A:A,A10,任务清单!I:I))
A11: B-10 | B11: 生成增强 | C11: 导演台服务 | D11: 导演台API | E11: 场景模型管理/人物模型参数存储/位置姿态参数/拖拽参数同步/拍照(截图渲染)/视角调整API | H11: 未开始 | J11: =SUMIF(任务清单!A:A,A11,任务清单!I:I) | K11: =SUMIF(任务清单!A:A,A11,任务清单!J:J) | L11: =IF(SUMIF(任务清单!A:A,A11,任务清单!I:I)=0,0,(SUMIFS(任务清单!I:I,任务清单!A:A,A11,任务清单!O:O,"已完成")+SUMIFS(任务清单!I:I,任务清单!A:A,A11,任务清单!O:O,"已取消"))/SUMIF(任务清单!A:A,A11,任务清单!I:I))
A12: B-11 | B12: 生成服务 | C12: 模型管理 | D12: 模型配置API | E12: 模型列表(文本/图片/视频/音频)/模型信息查询/参数约束/可用状态查询/消耗点数查询 | H12: 未开始 | J12: =SUMIF(任务清单!A:A,A12,任务清单!I:I) | K12: =SUMIF(任务清单!A:A,A12,任务清单!J:J) | L12: =IF(SUMIF(任务清单!A:A,A12,任务清单!I:I)=0,0,(SUMIFS(任务清单!I:I,任务清单!A:A,A12,任务清单!O:O,"已完成")+SUMIFS(任务清单!I:I,任务清单!A:A,A12,任务清单!O:O,"已取消"))/SUMIF(任务清单!A:A,A12,任务清单!I:I))
A13: B-12 | B13: 生成服务 | C13: 任务队列 | D13: 生成任务调度API | E13: 任务创建/参数校验/队列调度/状态管理(排队/执行/成功/失败)/WebSocket状态推送/幂等性控制/重试机制/任务历史存储 | H13: 未开始 | J13: =SUMIF(任务清单!A:A,A13,任务清单!I:I) | K13: =SUMIF(任务清单!A:A,A13,任务清单!J:J) | L13: =IF(SUMIF(任务清单!A:A,A13,任务清单!I:I)=0,0,(SUMIFS(任务清单!I:I,任务清单!A:A,A13,任务清单!O:O,"已完成")+SUMIFS(任务清单!I:I,任务清单!A:A,A13,任务清单!O:O,"已取消"))/SUMIF(任务清单!A:A,A13,任务清单!I:I))
... A48: B-47 | B48: 通用 | C48: 审计日志 | D48: 审计日志API | E48: 敏感操作日志记录(操作人/时间/对象/变更前后值/IP)/日志查询/日志导出 | H48: 未开始 | J48: =SUMIF(任务清单!A:A,A48,任务清单!I:I) | K48: =SUMIF(任务清单!A:A,A48,任务清单!J:J) | L48: =IF(SUMIF(任务清单!A:A,A48,任务清单!I:I)=0,0,(SUMIFS(任务清单!I:I,任务清单!A:A,A48,任务清单!O:O,"已完成")+SUMIFS(任务清单!I:I,任务清单!A:A,A48,任务清单!O:O,"已取消"))/SUMIF(任务清单!A:A,A48,任务清单!I:I))

Sheet 任务清单
A1: 功能编号 | B1: 任务编号 | C1: 阶段 | D1: 任务名称 | E1: 任务目标 | F1: 负责人 | G1: 开始日期 | H1: 结束日期 | I1: 预估(人天) | J1: 实际(人天) | K1: 优先级 | L1: 复杂度 | M1: 前置依赖 | N1: 风险项 | O1: 状态 | P1: 交付物 | Q1: 备注
A2: F-01 | B2: F-01-01 | C2: 画布管理页 | D2: 画布列表页 | E2: 画布列表展示(缩略图/名称/更新时间)/新建画布入口/空状态 | I2: 0.206 | J2: 0 | K2: P0 | L2: 中 | O2: 未开始 | P2: 画布列表页
A3: F-01 | B3: F-01-02 | C3: 画布管理页 | D3: 画布CRUD操作 | E3: 编辑画布名称(行内编辑)/删除画布(二次确认弹窗)/导入画布(上传JSON文件)/下载画布(导出JSON) | I3: 0.206 | J3: 0 | K3: P0 | L3: 中 | M3: F-01-01 | O3: 未开始
A4: F-02 | B4: F-02-01 | C4: 无限画布 | D4: 画布视口组件 | E4: 无限延展创作空间实现/画布拖拽平移/画布缩放(放大缩小)/适应视图/鼠标模式切换(选择/抓手)/快捷键 | I4: 0.343 | J4: 0 | K4: P0 | L4: 高 | M4: F-01-01 | N4: 大画布渲染性能 | O4: 未开始 | P4: 画布视口组件
A5: F-02 | B5: F-02-02 | C5: 无限画布 | D5: 一键整理功能 | E5: 自动排列所有节点/不重叠布局/连线指向保持 | I5: 0.137 | J5: 0 | K5: P0 | L5: 中 | M5: F-02-01 | N5: 布局算法复杂 | O5: 未开始
A6: F-03 | B6: F-03-01 | C6: 卡片管理 | D6: 卡片创建入口 | E6: 新建卡片(左侧添加按钮/右键画布/双击画布空白处3种方式)/卡片类型选择 | I6: 0.206 | J6: 0 | K6: P0 | L6: 中 | M6: F-02-01 | O6: 未开始 | P6: 卡片创建组件
A7: F-03 | B7: F-03-02 | C7: 卡片管理 | D7: 卡片交互操作 | E7: 卡片拖拽移动/卡片缩放/卡片复制/卡片删除/多卡片框选/删除影响提示 | I7: 0.274 | J7: 0 | K7: P0 | L7: 高 | M7: F-03-01 | N7: 节点过多卡顿 | O7: 未开始 | P7: 节点交互系统
A8: F-03 | B8: F-03-03 | C8: 卡片管理 | D8: 卡片编辑功能 | E8: 修改卡片内容/修改卡片参数/编辑面板UI | I8: 0.206 | J8: 0 | K8: P0 | L8: 中 | M8: F-03-02 | O8: 未开始 | P8: 卡片编辑面板
A9: F-04 | B9: F-04-01 | C9: 连线系统 | D9: 连线交互 | E9: 添加连线(输出端拖拽至输入端)/通过输出端呼出模态选择列表/一键创建下游节点并自动连线 | I9: 0.274 | J9: 0 | K9: P0 | L9: 中 | M9: F-03-01 | O9: 未开始 | P9: 连线交互组件
A10: F-04 | B10: F-04-02 | C10: 连线系统 | D10: 连线管理 | E10: 删除连线/连线状态可视化(蓝色有效/灰色无效/黑色选中)/连线曲线渲染 | I10: 0.206 | J10: 0 | K10: P0 | L10: 中 | M10: F-04-01 | O10: 未开始
A11: F-04 | B11: F-04-03 | C11: 连线系统 | D11: 连线校验 | E11: 兼容性校验/阻止自连接/阻止重复连接/不兼容提示 | I11: 0.137 | J11: 0 | K11: P0 | L11: 中 | M11: F-04-01 | O11: 未开始
A12: F-05 | B12: F-05-01 | C12: 编组功能 | D12: 编组创建 | E12: 框选多卡片创建编组/编组颜色选择 | I12: 0.137 | J12: 0 | K12: P1 | L12: 低 | M12: F-03-02 | O12: 未开始 | P12: 编组组件
A13: F-05 | B13: F-05-02 | C13: 编组功能 | D13: 编组布局 | E13: 网格排列(自动网格布局)/水平排列(自动水平布局) | I13: 0.137 | J13: 0 | K13: P1 | L13: 中 | M13: F-05-01 | O13: 未开始
A14: F-05 | B14: F-05-03 | C14: 编组功能 | D14: 编组操作 | E14: 取消编组(保留节点坐标连线)/下载编组内所有内容 | I14: 0.137 | J14: 0 | K14: P1 | L14: 低 | M14: F-05-01 | O14: 未开始
A15: F-06 | B15: F-06-01 | C15: 堆叠功能 | D15: 堆叠创建 | E15: 框选多卡片堆叠为一张卡片(展示拼图预览) | I15: 0.137 | J15: 0 | K15: P1 | L15: 低 | M15: F-03-02 | O15: 未开始 | P15: 堆叠组件
A16: F-06 | B16: F-06-02 | C16: 堆叠功能 | D16: 堆叠交互 | E16: 双击展开堆叠卡片/点击空白重新堆叠/拉出到画布(单独拉出某卡片) | I16: 0.206 | J16: 0 | K16: P1 | L16: 中 | M16: F-06-01 | O16: 未开始
A17: F-07 | B17: F-07-01 | C17: 文本卡片 | D17: 文本卡片组件 | E17: Markdown编辑渲染/提示词输入/上传参考/模型选择/参数设置(生成份数)/消耗预览/提交生成 | I17: 0.274 | J17: 0 | K17: P0 | L17: 中 | M17: F-03-02 | N17: Markdown兼容 | O17: 未开始 | P17: 文本卡片组件
A18: F-07 | B18: F-07-02 | C18: 文本卡片 | D18: 文本生成结果 | E18: 结果展示/编辑/保存素材库/生成历史列表/历史结果切换 | I18: 0.137 | J18: 0 | K18: P0 | L18: 低 | M18: F-07-01 | O18: 未开始
A19: F-08 | B19: F-08-01 | C19: 图片卡片 | D19: 图片卡片组件 | E19: 图片上传/参数选择(分辨率/风格/份数)/模型选择/消耗预览/提交生成 | I19: 0.274 | J19: 0 | K19: P0 | L19: 中 | M19: F-03-02 | O19: 未开始 | P19: 图片卡片组件
A20: F-08 | B20: F-08-02 | C20: 图片卡片 | D20: 图片结果展示 | E20: 生成历史列表/单图四宫格九宫格展示/全屏预览/下载/保存素材库/历史结果切换当前输出 | I20: 0.206 | J20: 0 | K20: P0 | L20: 中 | M20: F-08-01 | O20: 未开始
A21: F-09 | B21: F-09-01 | C21: 视频卡片 | D21: 视频卡片组件 | E21: AI生成视频入口/模型选择/参数选择(运镜/风格/份数)/消耗预览 | I21: 0.206 | J21: 0 | K21: P0 | L21: 中 | M21: F-03-02 | O21: 未开始 | P21: 视频卡片组件
A22: F-09 | B22: F-09-02 | C22: 视频卡片 | D22: 视频编辑操作 | E22: 剪辑(拖动首尾边界确认时间范围)/提取帧(拖动时间轴截取当前帧) | I22: 0.206 | J22: 0 | K22: P1 | L22: 中 | M22: F-09-01 | N22: 视频播放器 | O22: 未开始 | P22: 视频编辑面板
A23: F-09 | B23: F-09-03 | C23: 视频卡片 | D23: 视频结果与认证 | E23: 超分(选择目标分辨率)/认证(Seedance 2.0素材认证)/下载/存入素材库/全屏展示/生成历史 | I23: 0.137 | J23: 0 | K23: P1 | L23: 中 | M23: F-09-02 | N23: Seedance认证接口 | O23: 未开始
A24: F-10 | B24: F-10-01 | C24: 音频卡片 | D24: 音频卡片组件 | E24: 上传参考/AI生成音频/模型选择/参数选择(风格/份数)/消耗预览/试听播放器/下载/存入素材库 | I24: 0.206 | J24: 0 | K24: P0 | L24: 低 | M24: F-03-02 | O24: 未开始 | P24: 音频卡片组件
A25: F-11 | B25: F-11-01 | C25: 合成节点 | D25: 合成节点组件 | E25: 左侧接收多个视频节点输入/多段视频拼接预览列表/调整拼接顺序 | I25: 0.206 | J25: 0 | K25: P1 | L25: 中 | M25: F-09-01 | O25: 未开始 | P25: 合成节点组件
A26: F-11 | B26: F-11-02 | C26: 合成节点 | D26: 合成操作 | E26: 点击合成/消耗预览/合成结果播放与下载 | I26: 0.137 | J26: 0 | K26: P1 | L26: 低 | M26: F-11-01 | O26: 未开始
A27: F-12 | B27: F-12-01 | C27: 导演台 | D27: 导演台编辑页 | E27: 作为图片/视频节点上游输入/进入导演台编辑页面/3D场景渲染 | I27: 0.343 | J27: 0 | K27: P1 | L27: 高 | M27: F-03-02 | N27: 3D渲染性能 | O27: 未开始 | P27: 导演台组件
A28: F-12 | B28: F-12-02 | C28: 导演台 | D28: 模型与参数 | E28: 新增模型(从列表选择)/删除模型/修改基础模型位置与大小/修改人物模型颜色位置姿态/拖拽滚轴调整参数 | I28: 0.206 | J28: 0 | K28: P1 | L28: 中 | M28: F-12-01 | O28: 未开始
A29: F-12 | B29: F-12-03 | C29: 导演台 | D29: 拍照与视角 | E29: 调整视角/拍照(生成当前场景截图作为节点输出) | I29: 0.137 | J29: 0 | K29: P1 | L29: 中 | M29: F-12-02 | O29: 未开始
A30: F-13 | B30: F-13-01 | C30: 素材库 | D30: 素材库侧边栏 | E30: 侧边栏展示/图标模式与列表模式切换 | I30: 0.137 | J30: 0 | K30: P0 | L30: 低 | M30: F-03-01 | O30: 未开始 | P30: 素材库组件
A31: F-13 | B31: F-13-02 | C31: 素材库 | D31: 素材管理操作 | E31: 从画布卡片存入素材库/本地文件上传/拖拽素材到画布/导入画布/下载素材/替换素材(上传新文件)/删除素材(二次确认)/重命名素材/全屏预览素材 | I31: 0.274 | J31: 0 | K31: P0 | L31: 中 | M31: F-13-01 | O31: 未开始
A32: F-13 | B32: F-13-03 | C32: 素材库 | D32: 企业素材转移 | E32: 从个人素材库添加到企业素材库 | I32: 0.069 | J32: 0 | K32: P1 | L32: 低 | M32: F-13-02 | O32: 未开始
A33: F-14 | B33: F-14-01 | C33: Agent对话 | D33: 自然语言交互 | E33: 自然语言输入/Agent理解指令/画布上下文实时展示/全流程自动创作(灵感发散→资料整理→内容生成→结构排版) | I33: 0.343 | J33: 0 | K33: P0 | L33: 高 | M33: F-03-01 | N33: LLM理解准确度 | O33: 未开始 | P33: Agent对话核心
A34: F-14 | B34: F-14-02 | C34: Agent对话 | D34: 对话UI与建议 | E34: 多轮对话界面/创作建议/操作进度展示 | I34: 0.206 | J34: 0 | K34: P0 | L34: 中 | M34: F-14-01 | O34: 未开始
A35: F-15 | B35: F-15-01 | C35: Agent操作 | D35: 对话面板 | E35: 打开Agent对话框(右下角纸鹤图标)/收起对话框/动画过渡 | I35: 0.137 | J35: 0 | K35: P0 | L35: 低 | M35: F-01-01 | O35: 未开始 | P35: Agent面板UI
A36: F-15 | B36: F-15-02 | C36: Agent操作 | D36: 偏好与用量 | E36: 偏好设置(文本/图片/视频模型及分辨率选择)/查看当前对话用量(Token总量/各模型消耗量/点数消耗) | I36: 0.137 | J36: 0 | K36: P0 | L36: 中 | M36: F-15-01 | O36: 未开始
A37: F-16 | B37: F-16-01 | C37: Skill | D37: Skill列表与选择 | E37: Skill选择入口/预设Skill列表浏览/按名称描述搜索Skill/单击选中Skill添加到对话 | I37: 0.137 | J37: 0 | K37: P1 | L37: 低 | M37: F-15-01 | O37: 未开始 | P37: Skill选择UI
A38: F-16 | B38: F-16-02 | C38: Skill | D38: 新建Skill | E38: 空白创建(名称+描述+指令→保存)/从当前对话生成(Agent自动总结→检查修改→保存)/上传Skill文件(选择.md上传/格式校验) | I38: 0.206 | J38: 0 | K38: P1 | L38: 中 | M38: F-16-01 | O38: 未开始 | P38: Skill创建页
A39: F-16 | B39: F-16-03 | C39: Skill | D39: Skill管理 | E39: Skill管理与切换/Skill内容查看/删除Skill | I39: 0.069 | J39: 0 | K39: P1 | L39: 低 | M39: F-16-02 | O39: 未开始
A40: F-17 | B40: F-17-01 | C40: 对话历史 | D40: 对话历史页 | E40: 查看当前画布对话历史/查看其他画布对话历史/新建对话 | I40: 0.137 | J40: 0 | K40: P1 | L40: 低 | M40: F-15-01 | O40: 未开始 | P40: 对话历史页
...
